Workbook

Sheet สรุปผล
A1: รายงานผล Performance Test — SystemBOQ · รอบ 2 (หลังแก้)
A2: สร้างเมื่อ 23/10/2569 17:34 · ทดสอบบนเครื่องพัฒนาด้วย k6 · รายละเอียดวิธีทดสอบอยู่ที่แผ่นงาน 'วิธีทดสอบและเกณฑ์'
A4: รูปแบบ | B4: ผู้ใช้พร้อมกันสูงสุด | C4: ระยะเวลา (วินาที) | D4: จำนวนคำขอ | E4: ไม่สำเร็จ | F4: อัตรา error | G4: คำขอ/วินาที | H4: p95 ทั้งหมด (ms) | I4: ช้าสุด (ms) | J4: เส้นที่ไม่ผ่าน | K4: ผล
A5: Smoke test — ตรวจว่าทุกเส้นทำงาน | B5: 2 | C5: 31 | D5: =SUM('ผลรายเส้น API'!D5:D19) -> 148 | E5: =SUM('ผลรายเส้น API'!E5:E19) -> 0 | F5: =IF(D5=0,0,E5/D5) -> 0 | G5: =D5/C5 -> 4.7741935 | H5: 21.047793 | I5: 32.041161 | J5: =COUNTIF('ผลรายเส้น API'!M5:M19,"ไม่ผ่าน") -> 0 | K5: =IF(J5=0,"ผ่าน","ไม่ผ่าน") -> ผ่าน
A6: Load test — ใช้งานปกติต่อเนื่อง | B6: 40 | C6: 273 | D6: =SUM('ผลรายเส้น API'!D20:D34) -> 21126 | E6: =SUM('ผลรายเส้น API'!E20:E34) -> 0 | F6: =IF(D6=0,0,E6/D6) -> 0 | G6: =D6/C6 -> 77.384615 | H6: 14.887148 | I6: 65.2077 | J6: =COUNTIF('ผลรายเส้น API'!M20:M34,"ไม่ผ่าน") -> 0 | K6: =IF(J6=0,"ผ่าน","ไม่ผ่าน") -> ผ่าน
A7: Stress test — เพิ่มผู้ใช้จนเห็นขีดจำกัด | B7: 300 | C7: 274 | D7: =SUM('ผลรายเส้น API'!D35:D49) -> 81115 | E7: =SUM('ผลรายเส้น API'!E35:E49) -> 0 | F7: =IF(D7=0,0,E7/D7) -> 0 | G7: =D7/C7 -> 296.04015 | H7: 20.80897 | I7: 94.758784 | J7: =COUNTIF('ผลรายเส้น API'!M35:M49,"ไม่ผ่าน") -> 0 | K7: =IF(J7=0,"ผ่าน","ไม่ผ่าน") -> ผ่าน
A8: Spike test — ผู้ใช้พุ่งขึ้นกะทันหัน | B8: 300 | C8: 133 | D8: =SUM('ผลรายเส้น API'!D50:D64) -> 36992 | E8: =SUM('ผลรายเส้น API'!E50:E64) -> 0 | F8: =IF(D8=0,0,E8/D8) -> 0 | G8: =D8/C8 -> 278.13534 | H8: 35.17419 | I8: 98.858687 | J8: =COUNTIF('ผลรายเส้น API'!M50:M64,"ไม่ผ่าน") -> 0 | K8: =IF(J8=0,"ผ่าน","ไม่ผ่าน") -> ผ่าน
A9: PDF test — สร้าง PDF ใบเสนอราคาพร้อมกัน | B9: 5 | C9: 202 | D9: =SUM('ผลรายเส้น API'!D65:D65) -> 254 | E9: =SUM('ผลรายเส้น API'!E65:E65) -> 0 | F9: =IF(D9=0,0,E9/D9) -> 0 | G9: =D9/C9 -> 1.2574257 | H9: 1899.4902 | I9: 2023.8864 | J9: =COUNTIF('ผลรายเส้น API'!M65:M65,"ไม่ผ่าน") -> 0 | K9: =IF(J9=0,"ผ่าน","ไม่ผ่าน") -> ผ่าน
A10: รวม | D10: =SUM(D5:D9) -> 139635 | E10: =SUM(E5:E9) -> 0 | F10: =IF(D10=0,0,E10/D10) -> 0
A12: สรุปสั้น
A13: • หลังแก้ (รอบ 2) ใช้งานปกติ 40 คน: p95 15 ms (รอบ 1 = 53 ms) · error 0% จาก 21,127 คำขอ — ผ่านทุกเส้น
A14: • Stress ถึง 300 คน: p95 21 ms (รอบ 1 = 907 ms) · รับได้ 297 คำขอ/วินาที (รอบ 1 = 177) และยังไม่เจอเพดาน — ช่วงพีคทำได้ ~645 คำขอ/วินาที (รอบ 1 ค้างที่ ~246)
A15: • Spike พุ่งเป็น 300 คน: p95 35 ms (รอบ 1 = 1,521 ms) · ทุกรูปแบบผ่านเกณฑ์ (รอบ 1 ไม่ผ่าน 2 รูปแบบ)
A16: • สาเหตุหลักที่ดีขึ้น = gzip: ข้อมูลที่ส่งต่อคำขอลดจาก 10.7 KB เหลือ 2.9 KB (stress) · CPU ของ API เท่าเดิม (~13%) แต่รับคำขอได้มากขึ้น — คอขวดรอบ 1 คือการส่งข้อมูลก้อนใหญ่ ไม่ใช่ CPU (แก้ข้อสรุปเดิมของรอบ 1)
A17: • อุ่น Chromium: PDF ใบแรกหลังเปิดเครื่องครั้งแรก 8.5 วิ → 1.8 วิ · ตอนแคชของระบบอุ่นแล้วต่างกันราว 0.5 วิ · PDF ใบต่อ ๆ ไป ~1.7–2.0 วิ เท่าเดิม (งานวาดของ Chromium ไม่ได้แก้)
A18: • ตัวเลขเป็นของเครื่องพัฒนา — ใช้เทียบก่อน/หลังแก้ ไม่ใช่ความสามารถจริงของ VPS (2 vCPU)

Sheet เทียบรอบ
A1: เทียบผล รอบ 1 (ก่อนแก้) กับ รอบ 2 (หลังแก้)
A2: เปลี่ยน % = (รอบนี้ − รอบก่อน) ÷ รอบก่อน · ฟอนต์เขียว = ดีขึ้น · แดง = แย่ลง · ข้อมูลรวมขึ้นกับจำนวนคำขอ — ดูแถว 'ข้อมูลต่อคำขอ' ประกอบ
A4: รูปแบบ | B4: ตัวชี้วัด | C4: รอบ 1 (ก่อนแก้) | D4: รอบ 2 (หลังแก้) | E4: เปลี่ยน % | H4: รูปแบบ | I4: รอบ 1 (ก่อนแก้) | J4: รอบ 2 (หลังแก้)
A5: Smoke test — ตรวจว่าทุกเส้นทำงาน | B5: คำขอ/วินาที | C5: 4.320388 | D5: 4.8035378 | E5: =IF(OR(C5="",C5=0),"-",(D5-C5)/C5) -> 0.11183018 | H5: =LEFT(A6,FIND(" ",A6)-1) -> Smoke | I5: =C6 -> 58.215458 | J5: =D6 -> 21.047793
A6: Smoke test — ตรวจว่าทุกเส้นทำงาน | B6: p95 ทุกคำขอ (ms) | C6: 58.215458 | D6: 21.047793 | E6: =IF(OR(C6="",C6=0),"-",(D6-C6)/C6) -> -0.63845009 | H6: =LEFT(A13,FIND(" ",A13)-1) -> Load | I6: =C13 -> 52.908718 | J6: =D13 -> 14.887148
A7: Smoke test — ตรวจว่าทุกเส้นทำงาน | B7: p95 เส้นพนักงาน (ms) | C7: 77.443664 | D7: 23.163326 | E7: =IF(OR(C7="",C7=0),"-",(D7-C7)/C7) -> -0.70090095 | H7: =LEFT(A20,FIND(" ",A20)-1) -> Stress | I7: =C20 -> 906.77195 | J7: =D20 -> 20.80897
A8: Smoke test — ตรวจว่าทุกเส้นทำงาน | B8: ช้าสุด (ms) | C8: 99.697487 | D8: 32.041161 | E8: =IF(OR(C8="",C8=0),"-",(D8-C8)/C8) -> -0.67861616 | H8: =LEFT(A27,FIND(" ",A27)-1) -> Spike | I8: =C27 -> 1521.3348 | J8: =D27 -> 35.17419
A9: Smoke test — ตรวจว่าทุกเส้นทำงาน | B9: ข้อมูลที่ส่งกลับรวม (MB) | C9: 1.773118 | D9: 0.440627 | E9: =IF(OR(C9="",C9=0),"-",(D9-C9)/C9) -> -0.75149595 | H9: =LEFT(A34,FIND(" ",A34)-1) -> PDF | I9: =C34 -> 2155.2895 | J9: =D34 -> 1899.4902
A10: Smoke test — ตรวจว่าทุกเส้นทำงาน | B10: ข้อมูลต่อคำขอ (KB) | C10: 11.900121 | D10: 2.9572282 | E10: =IF(OR(C10="",C10=0),"-",(D10-C10)/C10) -> -0.75149595
A11: Smoke test — ตรวจว่าทุกเส้นทำงาน | B11: อัตรา error | C11: 0 | D11: 0 | E11: =IF(OR(C11="",C11=0),"-",(D11-C11)/C11) -> -
A12: Load test — ใช้งานปกติต่อเนื่อง | B12: คำขอ/วินาที | C12: 74.634123 | D12: 77.307146 | E12: =IF(OR(C12="",C12=0),"-",(D12-C12)/C12) -> 0.035815017
A13: Load test — ใช้งานปกติต่อเนื่อง | B13: p95 ทุกคำขอ (ms) | C13: 52.908718 | D13: 14.887148 | E13: =IF(OR(C13="",C13=0),"-",(D13-C13)/C13) -> -0.7186258
A14: Load test — ใช้งานปกติต่อเนื่อง | B14: p95 เส้นพนักงาน (ms) | C14: 58.65165 | D14: 16.344337 | E14: =IF(OR(C14="",C14=0),"-",(D14-C14)/C14) -> -0.72133201
A15: Load test — ใช้งานปกติต่อเนื่อง | B15: ช้าสุด (ms) | C15: 198.09479 | D15: 65.2077 | E15: =IF(OR(C15="",C15=0),"-",(D15-C15)/C15) -> -0.67082577
A16: Load test — ใช้งานปกติต่อเนื่อง | B16: ข้อมูลที่ส่งกลับรวม (MB) | C16: 236.72832 | D16: 61.89772 | E16: =IF(OR(C16="",C16=0),"-",(D16-C16)/C16) -> -0.73852845
A17: Load test — ใช้งานปกติต่อเนื่อง | B17: ข้อมูลต่อคำขอ (KB) | C17: 11.619138 | D17: 2.9297922 | E17: =IF(OR(C17="",C17=0),"-",(D17-C17)/C17) -> -0.74784772
A18: Load test — ใช้งานปกติต่อเนื่อง | B18: อัตรา error | C18: 0 | D18: 0 | E18: =IF(OR(C18="",C18=0),"-",(D18-C18)/C18) -> -
A19: Stress test — เพิ่มผู้ใช้จนเห็นขีดจำกัด | B19: คำขอ/วินาที | C19: 176.84559 | D19: 296.4848 | E19: =IF(OR(C19="",C19=0),"-",(D19-C19)/C19) -> 0.67651789
A20: Stress test — เพิ่มผู้ใช้จนเห็นขีดจำกัด | B20: p95 ทุกคำขอ (ms) | C20: 906.77195 | D20: 20.80897 | E20: =IF(OR(C20="",C20=0),"-",(D20-C20)/C20) -> -0.9770516
A21: Stress test — เพิ่มผู้ใช้จนเห็นขีดจำกัด | B21: p95 เส้นพนักงาน (ms) | C21: 1119.7195 | D21: 24.222331 | E21: =IF(OR(C21="",C21=0),"-",(D21-C21)/C21) -> -0.9783675
... A38: PDF test — สร้าง PDF ใบเสนอราคาพร้อมกัน | B38: อัตรา error | C38: 0 | D38: 0 | E38: =IF(OR(C38="",C38=0),"-",(D38-C38)/C38) -> -
A40: p95 รายเส้น API (ms)
A41: รูปแบบ · เส้น API | B41: ทำอะไร | C41: รอบ 1 (ก่อนแก้) | D41: รอบ 2 (หลังแก้) | E41: เปลี่ยน %
A42: load · public:house-designs | B42: รายการแบบบ้าน | C42: 18.152015 | D42: 6.2646372 | E42: =IF(C42=0,"-",(D42-C42)/C42) -> -0.65487924
A43: load · public:house-designs-featured | B43: แบบบ้านแนะนำ (หน้าแรก) | C43: 17.894407 | D43: 6.0394934 | E43: =IF(C43=0,"-",(D43-C43)/C43) -> -0.66249269
A44: load · public:portfolio | B44: รายการผลงาน | C44: 17.168959 | D44: 5.6932541 | E44: =IF(C44=0,"-",(D44-C44)/C44) -> -0.66839841
A45: load · public:settings | B45: ค่าตั้งเว็บ (ชื่อบริษัท รูปหน้าเว็บ) | C45: 19.045265 | D45: 7.26916 | E45: =IF(C45=0,"-",(D45-C45)/C45) -> -0.61832192
A46: load · staff:customers | B46: แฟ้มลูกค้า | C46: 32.930021 | D46: 10.086809 | E46: =IF(C46=0,"-",(D46-C46)/C46) -> -0.69368958
A47: load · staff:dashboard-pipeline | B47: แดชบอร์ด — ท่อขาย | C47: 30.073479 | D47: 9.5593585 | E47: =IF(C47=0,"-",(D47-C47)/C47) -> -0.68213327
A48: load · staff:dashboard-summary | B48: แดชบอร์ด — สรุป | C48: 30.209812 | D48: 11.02147 | E48: =IF(C48=0,"-",(D48-C48)/C48) -> -0.63516918
A49: load · staff:leads | B49: คำขอลูกค้า | C49: 27.752469 | D49: 8.623344 | E49: =IF(C49=0,"-",(D49-C49)/C49) -> -0.68927651
A50: load · staff:materials | B50: คลังวัสดุ (121 รายการ) | C50: 59.025598 | D50: 16.962394 | E50: =IF(C50=0,"-",(D50-C50)/C50) -> -0.71262649
A51: load · staff:me | B51: ข้อมูลผู้ใช้ที่ล็อกอิน | C51: 19.32801 | D51: 7.745621 | E51: =IF(C51=0,"-",(D51-C51)/C51) -> -0.59925408
A52: load · staff:notifications | B52: การแจ้งเตือน | C52: 25.403705 | D52: 7.8439955 | E52: =IF(C52=0,"-",(D52-C52)/C52) -> -0.69122632
A53: load · staff:project-boq | B53: BOQ ของโครงการ (178 รายการ) | C53: 71.726135 | D53: 20.132728 | E53: =IF(C53=0,"-",(D53-C53)/C53) -> -0.71931113
... A71: stress · staff:projects-list | B71: รายการโครงการ | C71: 1060.9414 | D71: 22.705221 | E71: =IF(C71=0,"-",(D71-C71)/C71) -> -0.97859899
A73: PDF ใบแรกหลังเปิด API ใหม่ — อุ่น Chromium ตอนเปิด (PDF_WARMUP) ปิด vs เปิด
A74: อุ่น Chromium | B74: ครั้งที่เปิด API | C74: PDF ใบที่ | D74: วินาที
A75: ปิด | B75: 1 | C75: 1 | D75: 8.549167
A76: ปิด | B76: 1 | C76: 2 | D76: 1.769163
...

Sheet วิธีทดสอบและเกณฑ์
A1: วิธีทดสอบและเกณฑ์ตัดสิน
A2: Performance test ระบบ SystemBOQ บนเครื่องพัฒนา (ไม่ได้ทดสอบเว็บจริงที่ deploy)
A4: สภาพแวดล้อม
A5: หัวข้อ | B5: รายละเอียด
A6: วันที่ทดสอบ | B6: 23 ตุลาคม 2569 — รอบ 1: 16:30–16:47 น. (ก่อนแก้) · รอบ 2: 17:05–17:31 น. (หลังแก้)
A7: โค้ดที่ทดสอบ | B7: รอบ 1: commit 1be46db · รอบ 2: 1be46db + แก้ขั้น 2 (gzip ด้วย compression + อุ่น Chromium ตอนเปิดเซิร์ฟเวอร์) ยังไม่ commit
A8: สิ่งที่ต่างระหว่างรอบ | B8: โค้ดฝั่ง API 2 จุดเท่านั้น · สคริปต์ k6 ส่ง Accept-Encoding: gzip, deflate, br แบบเบราว์เซอร์ (รอบ 1 เซิร์ฟเวอร์ไม่บีบอัด หัวนี้จึงไม่มีผล) · รูปแบบโหลด ข้อมูล เครื่อง เหมือนเดิมทุกอย่าง
A9: เครื่องที่ทดสอบ | B9: เครื่องพัฒนา Windows 11 · Intel Core i5-14500HX (14 คอร์ / 20 เธรด) · RAM 15.7 GB
A10: API | B10: Node.js 22.19 โหมดพัฒนา (tsx watch) · 1 โปรเซส · ไม่ส่งอีเมลจริง (MAIL_TRANSPORT=silent)
A11: ฐานข้อมูล | B11: PostgreSQL 17.10 ในคอนเทนเนอร์ Docker · ข้อมูล dev: โครงการ 10 · วัสดุ 121 · หมวดงาน 163
A12: โครงการที่ใช้ทดสอบ | B12: บ้านพักอาศัย 2 ชั้น — BOQ 178 รายการ + ใบเสนอราคา 1 ใบ (ใช้สร้าง PDF)
A13: เครื่องมือ | B13: k6 v2.3.0 (grafana/k6 ในคอนเทนเนอร์ Docker) ยิงไปที่ API ผ่าน host.docker.internal:4000
A14: บัญชีที่ใช้ | B14: บัญชีพนักงานชั่วคราว (ADMIN) สร้างก่อนทดสอบและลบหลังทดสอบ · ล็อกอินครั้งเดียวแล้วทุกคนใช้ session เดียวกัน
A16: เกณฑ์ตัดสิน (แก้ตัวเลขได้ — แผ่นงานอื่นอ้างช่องเหล่านี้)
A17: เกณฑ์ | B17: ค่า
A18: เวลาตอบ p95 ของเส้นอ่านข้อมูล ไม่เกิน (ms) | B18: 800
A19: เวลาตอบ p95 ของการสร้าง PDF ไม่เกิน (ms) | B19: 15000
A20: อัตรา error ไม่เกิน | B20: 0.01
A21: ที่มาของเกณฑ์: ผู้ทดสอบกำหนดเอง (ระบบภายในบริษัท ผู้ใช้ไม่เกินหลักสิบคน) — p95 = 95% ของคำขอเร็วกว่าค่านี้
A23: รูปแบบการทดสอบ
A24: รูปแบบ | B24: รูปแบบโหลด
A25: Smoke test — ตรวจว่าทุกเส้นทำงาน | B25: พนักงาน 1 + ผู้เข้าชม 1 คน 30 วินาที
A26: Load test — ใช้งานปกติต่อเนื่อง | B26: ไต่ขึ้น 1 นาที → พนักงาน 20 + ผู้เข้าชม 20 คน (รวม 40) ค้าง 3 นาที → ลง 30 วินาที
A27: Stress test — เพิ่มผู้ใช้จนเห็นขีดจำกัด | B27: ไต่เป็นขั้นนาทีละขั้น: กลุ่มละ 25 → 50 → 100 → 150 คน (รวมสูงสุด 300) → ลง 30 วินาที
A28: Spike test — ผู้ใช้พุ่งขึ้นกะทันหัน | B28: กลุ่มละ 5 คน 30 วินาที → พุ่งเป็นกลุ่มละ 150 (รวม 300) ใน 10 วินาที ค้าง 40 วินาที → ลดกลับ 5 คน
A29: PDF test — สร้าง PDF ใบเสนอราคาพร้อมกัน | B29: สร้าง PDF ใบเสนอราคาพร้อมกัน 1 → 3 → 5 คน ระดับละ 1 นาที
A31: สิ่งที่ผู้ใช้จำลองทำ
A32: กลุ่ม | B32: ลำดับการใช้งาน
A33: ผู้เข้าชมเว็บลูกค้า | B33: ค่าตั้งเว็บ → แบบบ้านแนะนำ → รายการแบบบ้าน → รายการผลงาน → พักอ่าน 1–3 วินาที (ไม่ต้องล็อกอิน)
A34: พนักงาน | B34: ข้อมูลผู้ใช้ → แดชบอร์ด (สรุป + ท่อขาย) → แจ้งเตือน → พัก 1 วิ → รายการโครงการ → รายละเอียดโครงการ → BOQ → ใบเสนอราคา → พัก 1 วิ → คลังวัสดุ → แฟ้มลูกค้า → คำขอลูกค้า → พัก 1–3 วิ
A35: สร้าง PDF | B35: ขอ PDF ใบเสนอราคา (Chromium วาดเอกสาร) → พัก 1 วินาที
A37: ข้อจำกัด
A38: • ทดสอบบนเครื่องพัฒนา ไม่ใช่ VPS จริง (VPS = 2 vCPU / RAM 8 GB) — ใช้เทียบก่อน/หลังแก้ได้ แต่ตัวเลขไม่เท่าระบบจริง
A39: • API รันโหมดพัฒนา (tsx) ช้ากว่าไฟล์ที่ build แล้วบนระบบจริงเล็กน้อย
A40: • k6 กับระบบรันเครื่องเดียวกัน ไม่มีเวลาเดินทางของเน็ต และ k6 แย่ง CPU บางส่วน
A41: • k6 อยู่ในคอนเทนเนอร์ Docker ยิงเข้าเครื่องผ่านเครือข่ายของ Docker Desktop ซึ่งส่งข้อมูลก้อนใหญ่ได้ช้า — ผลของ gzip ในเครื่องจึงอาจมากกว่าบนอินเทอร์เน็ตจริง (บนเน็ตจริงยังได้ประโยชน์ โดยเฉพาะมือถือ แต่ตัวเลขไม่เท่า)
A42: • ทดสอบเฉพาะการอ่านข้อมูล + สร้าง PDF — ไม่ได้ทดสอบการบันทึก/แก้ไข และไม่ยิงเส้นที่ส่งอีเมลหรือมีเพดานจำกัด (สมัคร ลืมรหัส ส่งคำขอติดต่อ)
A43: • ไม่ได้วัดเวลาโหลดหน้าเว็บ (HTML/JS/รูป) เพราะเครื่องพัฒนาใช้ Vite dev server ไม่ใช่ไฟล์ build จริง
A44: • Load test ยาว 4.5 นาที — สั้นเกินกว่าจะสรุปเรื่องหน่วยความจำรั่วระยะยาว

Sheet ผลรายเส้น API
A1: ผลรายเส้น API
A2: เวลาตอบเป็นมิลลิวินาที (ms) คิดจากทุกคำขอ · ผ่าน = p95 ไม่เกินเกณฑ์ และ error ไม่เกินเกณฑ์ (สูตรอ้างแผ่นงาน 'วิธีทดสอบและเกณฑ์')
A4: รูปแบบ | B4: เส้น API | C4: ทำอะไร | D4: จำนวนคำขอ | E4: ไม่สำเร็จ | F4: อัตรา error | G4: เฉลี่ย | H4: p50 | I4: p90 | J4: p95 | K4: p99 | L4: สูงสุด | M4: ผล
A5: smoke | B5: public:house-designs | C5: รายการแบบบ้าน | D5: 15 | E5: 0 | F5: =IF(D5=0,0,E5/D5) -> 0 | G5: 4.0700361 | H5: 3.27688 | I5: 5.485438 | J5: 7.5005488 | K5: 11.099801 | L5: 11.999614 | M5: =IF(AND(J5<=วิธีทดสอบและเกณฑ์!$B$18,F5<=วิธีทดสอบและเกณฑ์!$B$20),"ผ่าน","ไม่ผ่าน") -> ผ่าน
A6: smoke | B6: public:house-designs-featured | C6: แบบบ้านแนะนำ (หน้าแรก) | D6: 15 | E6: 0 | F6: =IF(D6=0,0,E6/D6) -> 0 | G6: 4.2560453 | H6: 3.716591 | I6: 5.624444 | J6: 6.5983358 | K6: 7.9023664 | L6: 8.228374 | M6: =IF(AND(J6<=วิธีทดสอบและเกณฑ์!$B$18,F6<=วิธีทดสอบและเกณฑ์!$B$20),"ผ่าน","ไม่ผ่าน") -> ผ่าน
A7: smoke | B7: public:portfolio | C7: รายการผลงาน | D7: 15 | E7: 0 | F7: =IF(D7=0,0,E7/D7) -> 0 | G7: 3.8248639 | H7: 3.371112 | I7: 5.4245648 | J7: 6.3904255 | K7: 7.5565947 | L7: 7.848137 | M7: =IF(AND(J7<=วิธีทดสอบและเกณฑ์!$B$18,F7<=วิธีทดสอบและเกณฑ์!$B$20),"ผ่าน","ไม่ผ่าน") -> ผ่าน
A8: smoke | B8: public:settings | C8: ค่าตั้งเว็บ (ชื่อบริษัท รูปหน้าเว็บ) | D8: 15 | E8: 0 | F8: =IF(D8=0,0,E8/D8) -> 0 | G8: 6.478167 | H8: 5.515507 | I8: 7.8170158 | J8: 11.384613 | K8: 17.523475 | L8: 19.058191 | M8: =IF(AND(J8<=วิธีทดสอบและเกณฑ์!$B$18,F8<=วิธีทดสอบและเกณฑ์!$B$20),"ผ่าน","ไม่ผ่าน") -> ผ่าน
A9: smoke | B9: staff:customers | C9: แฟ้มลูกค้า | D9: 8 | E9: 0 | F9: =IF(D9=0,0,E9/D9) -> 0 | G9: 9.0210897 | H9: 8.480672 | I9: 11.270181 | J9: 12.228426 | K9: 12.995023 | L9: 13.186672 | M9: =IF(AND(J9<=วิธีทดสอบและเกณฑ์!$B$18,F9<=วิธีทดสอบและเกณฑ์!$B$20),"ผ่าน","ไม่ผ่าน") -> ผ่าน
A10: smoke | B10: staff:dashboard-pipeline | C10: แดชบอร์ด — ท่อขาย | D10: 8 | E10: 0 | F10: =IF(D10=0,0,E10/D10) -> 0 | G10: 9.4571613 | H10: 8.490327 | I10: 13.218091 | J10: 15.061825 | K10: 16.536811 | L10: 16.905558 | M10: =IF(AND(J10<=วิธีทดสอบและเกณฑ์!$B$18,F10<=วิธีทดสอบและเกณฑ์!$B$20),"ผ่าน","ไม่ผ่าน") -> ผ่าน
A11: smoke | B11: staff:dashboard-summary | C11: แดชบอร์ด — สรุป | D11: 8 | E11: 0 | F11: =IF(D11=0,0,E11/D11) -> 0 | G11: 11.140626 | H11: 7.8872525 | I11: 17.091299 | J11: 24.56623 | K11: 30.546175 | L11: 32.041161 | M11: =IF(AND(J11<=วิธีทดสอบและเกณฑ์!$B$18,F11<=วิธีทดสอบและเกณฑ์!$B$20),"ผ่าน","ไม่ผ่าน") -> ผ่าน
A12: smoke | B12: staff:leads | C12: คำขอลูกค้า | D12: 8 | E12: 0 | F12: =IF(D12=0,0,E12/D12) -> 0 | G12: 6.8956053 | H12: 6.931944 | I12: 8.1090148 | J12: 8.4388079 | K12: 8.7026424 | L12: 8.768601 | M12: =IF(AND(J12<=วิธีทดสอบและเกณฑ์!$B$18,F12<=วิธีทดสอบและเกณฑ์!$B$20),"ผ่าน","ไม่ผ่าน") -> ผ่าน
A13: smoke | B13: staff:materials | C13: คลังวัสดุ (121 รายการ) | D13: 8 | E13: 0 | F13: =IF(D13=0,0,E13/D13) -> 0 | G13: 16.699278 | H13: 15.190812 | I13: 22.969581 | J13: 24.447577 | K13: 25.629974 | L13: 25.925573 | M13: =IF(AND(J13<=วิธีทดสอบและเกณฑ์!$B$18,F13<=วิธีทดสอบและเกณฑ์!$B$20),"ผ่าน","ไม่ผ่าน") -> ผ่าน
A14: smoke | B14: staff:me | C14: ข้อมูลผู้ใช้ที่ล็อกอิน | D14: 8 | E14: 0 | F14: =IF(D14=0,0,E14/D14) -> 0 | G14: 4.9391395 | H14: 4.5043025 | I14: 6.4140035 | J14: 6.7296948 | K14: 6.9822477 | L14: 7.045386 | M14: =IF(AND(J14<=วิธีทดสอบและเกณฑ์!$B$18,F14<=วิธีทดสอบและเกณฑ์!$B$20),"ผ่าน","ไม่ผ่าน") -> ผ่าน
A15: smoke | B15: staff:notifications | C15: การแจ้งเตือน | D15: 8 | E15: 0 | F15: =IF(D15=0,0,E15/D15) -> 0 | G15: 6.0254156 | H15: 5.496702 | I15: 8.0670613 | J15: 8.2987232 | K15: 8.4840526 | L15: 8.530385 | M15: =IF(AND(J15<=วิธีทดสอบและเกณฑ์!$B$18,F15<=วิธีทดสอบและเกณฑ์!$B$20),"ผ่าน","ไม่ผ่าน") -> ผ่าน
A16: smoke | B16: staff:project-boq | C16: BOQ ของโครงการ (178 รายการ) | D16: 8 | E16: 0 | F16: =IF(D16=0,0,E16/D16) -> 0 | G16: 17.52951 | H16: 17.465705 | I16: 19.505813 | J16: 19.66865 | K16: 19.798921 | L16: 19.831488 | M16: =IF(AND(J16<=วิธีทดสอบและเกณฑ์!$B$18,F16<=วิธีทดสอบและเกณฑ์!$B$20),"ผ่าน","ไม่ผ่าน") -> ผ่าน
... A64: spike | B64: staff:projects-list | C64: รายการโครงการ | D64: 1936 | E64: 0 | F64: =IF(D64=0,0,E64/D64) -> 0 | G64: 17.304314 | H64: 13.374371 | I64: 34.5229 | J64: 40.746411 | K64: 51.508235 | L64: 72.561468 | M64: =IF(AND(J64<=วิธีทดสอบและเกณฑ์!$B$18,F64<=วิธีทดสอบและเกณฑ์!$B$20),"ผ่าน","ไม่ผ่าน") -> ผ่าน
A65: pdf | B65: pdf:quote | C65: สร้าง PDF ใบเสนอราคา | D65: 254 | E65: 0 | F65: =IF(D65=0,0,E65/D65) -> 0 | G65: 1343.0895 | H65: 1312.333 | I65: 1617.7483 | J65: 1899.4902 | K65: 1925.5632 | L65: 2023.8864 | M65: =IF(AND(J65<=วิธีทดสอบและเกณฑ์!$B$19,F65<=วิธีทดสอบและเกณฑ์!$B$20),"ผ่าน","ไม่ผ่าน") -> ผ่าน

Sheet ผลตามช่วงเวลา
A1: ผลตามช่วงเวลา
A2: แต่ละแถว = 15 วินาที · ผู้ใช้พร้อมกัน = รวมทุกกลุ่ม · ใช้ดูว่าเวลาตอบเปลี่ยนไปอย่างไรเมื่อผู้ใช้เพิ่มขึ้น
A4: รูปแบบ | B4: วินาทีที่ | C4: ผู้ใช้พร้อมกัน | D4: คำขอ | E4: คำขอ/วินาที | F4: p95 (ms) | G4: error
A5: load | B5: 0 | C5: 10 | D5: 226 | E5: =D5/15 -> 15.066667 | F5: 16.595403 | G5: =IF(D5=0,0,0/D5) -> 0
A6: load | B6: 15 | C6: 20 | D6: 576 | E6: =D6/15 -> 38.4 | F6: 14.999671 | G6: =IF(D6=0,0,0/D6) -> 0
A7: load | B7: 30 | C7: 30 | D7: 943 | E7: =D7/15 -> 62.866667 | F7: 16.994596 | G7: =IF(D7=0,0,0/D7) -> 0
A8: load | B8: 45 | C8: 40 | D8: 1259 | E8: =D8/15 -> 83.933333 | F8: 16.710947 | G8: =IF(D8=0,0,0/D8) -> 0
A9: load | B9: 60 | C9: 40 | D9: 1373 | E9: =D9/15 -> 91.533333 | F9: 14.548787 | G9: =IF(D9=0,0,0/D9) -> 0
A10: load | B10: 75 | C10: 40 | D10: 1416 | E10: =D10/15 -> 94.4 | F10: 16.405281 | G10: =IF(D10=0,0,0/D10) -> 0
A11: load | B11: 90 | C11: 40 | D11: 1406 | E11: =D11/15 -> 93.733333 | F11: 15.004863 | G11: =IF(D11=0,0,0/D11) -> 0
A12: load | B12: 105 | C12: 40 | D12: 1416 | E12: =D12/15 -> 94.4 | F12: 14.127142 | G12: =IF(D12=0,0,0/D12) -> 0
A13: load | B13: 120 | C13: 40 | D13: 1404 | E13: =D13/15 -> 93.6 | F13: 15.373168 | G13: =IF(D13=0,0,0/D13) -> 0
A14: load | B14: 135 | C14: 40 | D14: 1414 | E14: =D14/15 -> 94.266667 | F14: 14.070729 | G14: =IF(D14=0,0,0/D14) -> 0
A15: load | B15: 150 | C15: 40 | D15: 1399 | E15: =D15/15 -> 93.266667 | F15: 13.788809 | G15: =IF(D15=0,0,0/D15) -> 0
A16: load | B16: 165 | C16: 40 | D16: 1397 | E16: =D16/15 -> 93.133333 | F16: 13.752504 | G16: =IF(D16=0,0,0/D16) -> 0
... A66: pdf | B66: 195 | C66: 5 | D66: 10 | E66: =D66/15 -> 0.66666667 | F66: 1845.3946 | G66: =IF(D66=0,0,0/D66) -> 0

Sheet ทรัพยากรเครื่อง
A1: ทรัพยากรเครื่องระหว่างทดสอบ
A2: เก็บทุก 5 วินาที · CPU ของ API คิดเป็น % ของทั้งเครื่อง (ทุกคอร์รวม = 100%) · ฐานข้อมูล = คอนเทนเนอร์ postgres (100% = 1 คอร์)
A4: รูปแบบ | B4: วินาทีที่ | C4: API CPU % | D4: API RAM (MB) | E4: DB CPU % | F4: DB RAM (MB)
A5: smoke | B5: 0 | C5: 0.2 | D5: 148 | E5: 1.43 | F5: 309
A6: smoke | B6: 7 | C6: 0.2 | D6: 155 | E6: 0.96 | F6: 312
A7: smoke | B7: 13 | C7: 0.2 | D7: 160 | E7: 2.44 | F7: 313
A8: smoke | B8: 19 | C8: 0.2 | D8: 160 | E8: 0.65 | F8: 315
A9: smoke | B9: 26 | C9: 0 | D9: 165 | E9: 0.01 | F9: 312
A11: load | B11: 0 | C11: 0.1 | D11: 173 | E11: 3.79 | F11: 316
A12: load | B12: 6 | C12: 0.4 | D12: 172 | E12: 1.72 | F12: 321
A13: load | B13: 13 | C13: 0.6 | D13: 177 | E13: 2.56 | F13: 322
A14: load | B14: 19 | C14: 0.9 | D14: 183 | E14: 2.22 | F14: 327
A15: load | B15: 25 | C15: 1.2 | D15: 183 | E15: 3.9 | F15: 330
A16: load | B16: 32 | C16: 1.3 | D16: 187 | E16: 4.49 | F16: 334
A17: load | B17: 38 | C17: 1.5 | D17: 188 | E17: 5.07 | F17: 353
... A154: pdf | B154: 194 | C154: 0.7 | D154: 234 | E154: 0.01 | F154: 272

Sheet ข้อสังเกต
A1: ข้อสังเกตและข้อเสนอแนะ
A2: อ่านจากผลในแผ่นงานอื่น · ความรุนแรง: สูง = ควรแก้ก่อนผู้ใช้เพิ่ม · กลาง = ควรแก้ · ต่ำ = ทราบไว้
A4: # | B4: หัวข้อ | C4: สิ่งที่พบ (ตัวเลขจากผลทดสอบ) | D4: สาเหตุที่น่าจะเป็น | E4: ข้อเสนอแนะ | F4: ความรุนแรง
A5: 1 | B5: gzip (แก้แล้ว) | C5: Load p95 53→15 ms · Stress p95 907→21 ms · Spike p95 1,521→35 ms · BOQ ของโครงการช่วง stress 1,864→38 ms · ข้อมูลที่ส่งกลับ (load) 236.7→61.9 MB ทั้งที่คำขอมากขึ้น | D5: คำตอบ JSON ก้อนใหญ่ (50–70 KB) ไม่ถูกบีบอัด · หลังบีบเหลือ 8–9 KB | E5: deploy ขึ้นระบบจริง (ขั้น 4) — เว็บจริงจะส่งข้อมูลน้อยลงราว 4 เท่า โดยเฉพาะผู้ใช้มือถือ | F5: ต่ำ
A6: 2 | B6: แก้ข้อสรุปเรื่องคอขวดของรอบ 1 | C6: รอบ 1 สรุปว่าคอขวดคือ Node 1 โปรเซส · รอบ 2 CPU ของ API สูงสุด 12.5% (รอบ 1 = 13.0%) แต่รับคำขอได้ 297/วินาที (รอบ 1 = 177) และช่วงพีค ~645/วินาที | D6: ถ้าคอขวดคือ CPU รอบ 2 ต้องติดที่ CPU เท่าเดิม — ตัวเลขชี้ว่ารอบ 1 ติดที่การส่งข้อมูลก้อนใหญ่ (ส่วนหนึ่งเป็นเครือข่ายของ Docker Desktop ระหว่าง k6 กับเครื่อง) | E6: ยังไม่ต้องรัน API หลายตัว — ที่ 300 คนยังเหลือ CPU มาก · ถ้าต้องหาเพดานจริง ให้ดันเกิน 300 คน หรือยิงจากเครื่องอื่นแทน Docker ในเครื่องเดียวกัน | F6: ต่ำ
A7: 3 | B7: อุ่น Chromium (แก้แล้ว) | C7: PDF ใบแรกหลังเปิด API: ปิดอุ่น 8.55 วิ (เปิดเครื่องครั้งแรก) / 2.35 วิ (แคชอุ่น) · เปิดอุ่น 1.84 / 1.86 วิ · อุ่นใช้เวลา 0.6 วิ เบื้องหลัง | D7: การเปิด Chromium + โหลดไฟล์ครั้งแรกจากดิสก์ | E7: deploy (ขั้น 4) — บน VPS เปิดคอนเทนเนอร์ใหม่ทุกครั้งที่ deploy = ตรงกับกรณีเปิดเครื่องครั้งแรกที่ได้ผลมากสุด | F7: ต่ำ
A8: 4 | B8: สร้าง PDF ใบละ ~2 วินาที | C8: รอบ 2 p95 1,899 ms (รอบ 1 = 2,155) · 255 ใบ error 0% · 1–5 คนพร้อมกันเวลาใกล้เคียงกัน | D8: เวลาส่วนใหญ่อยู่ที่ Chromium วาดเอกสารหลายหน้า (ไม่ได้แก้ในรอบนี้) | E8: ยอมรับได้สำหรับเอกสารที่กดออกเป็นครั้งคราว · ถ้าต้องเร็วขึ้น: เก็บ PDF ที่ออกแล้วไว้ใช้ซ้ำเมื่อเนื้อหาไม่เปลี่ยน | F8: ต่ำ
A9: 5 | B9: ฐานข้อมูล | C9: รอบ 2 ฐานข้อมูลใช้ CPU สูงสุด 41–44% ของคอร์เดียว (รอบ 1 ≤ 24%) เพราะรับคำขอได้มากขึ้น · RAM ≤ 175 MB | D9: คำขอต่อวินาทีเพิ่ม | E9: ยังเหลือมาก · ถ้าผู้ใช้เพิ่มเป็นหลายร้อยคนพร้อมกันค่อยดูดัชนีของเส้นที่ช้าสุด | F9: ต่ำ
A10: 6 | B10: หน่วยความจำ | C10: API 242–374 MB · ฐานข้อมูล ≤ 175 MB ทั้งสองรอบ ไม่เพิ่มขึ้นต่อเนื่อง | D10: - | E10: ใช้ได้กับ VPS 8 GB · ทดสอบยาวหลายชั่วโมง (soak) ถ้าต้องการยืนยันเรื่องหน่วยความจำรั่ว | F10: ต่ำ
